<?xml version="1.0" encoding="utf-8"?>
<!-- This URDF was automatically created by SolidWorks to URDF Exporter! Originally created by Stephen Brawner (brawner@gmail.com) 
     Commit Version: 1.6.0-4-g7f85cfe  Build Version: 1.6.7995.38578
     For more information, please see http://wiki.ros.org/sw_urdf_exporter -->
<robot
  name="Aura_robot">
  <link
    name="base_link">
    <inertial>
      <origin
        xyz="0.077445 0.11132 0.20156"
        rpy="0 0 0" />
      <mass
        value="1.0167" />
      <inertia
        ixx="0.001835"
        ixy="1.2918E-06"
        ixz="2.9491E-07"
        iyy="0.0068512"
        iyz="-7.4114E-08"
        izz="0.0051708" />
    </inertial>
    <visual>
      <origin
        xyz="0 0 0"
        rpy="0 0 0" />
      <geometry>
        <mesh
          filename="package://Aura_robot/meshes/base_link.STL" />
      </geometry>
      <material
        name="">
        <color
          rgba="0.79216 0.81961 0.93333 1" />
      </material>
    </visual>
    <collision>
      <origin
        xyz="0 0 0"
        rpy="0 0 0" />
      <geometry>
        <mesh
          filename="package://Aura_robot/meshes/base_link.STL" />
      </geometry>
    </collision>
  </link>
  <link
    name="link_1">
    <inertial>
      <origin
        xyz="1.4647E-05 0.018092 0.0010409"
        rpy="0 0 0" />
      <mass
        value="0.15819" />
      <inertia
        ixx="6.1613E-05"
        ixy="2.1214E-09"
        ixz="-5.1761E-08"
        iyy="0.00010881"
        iyz="7.5578E-08"
        izz="6.2579E-05" />
    </inertial>
    <visual>
      <origin
        xyz="0 0 0"
        rpy="0 0 0" />
      <geometry>
        <mesh
          filename="package://Aura_robot/meshes/link_1.STL" />
      </geometry>
      <material
        name="">
        <color
          rgba="0.79216 0.81961 0.93333 1" />
      </material>
    </visual>
    <collision>
      <origin
        xyz="0 0 0"
        rpy="0 0 0" />
      <geometry>
        <mesh
          filename="package://Aura_robot/meshes/link_1.STL" />
      </geometry>
    </collision>
  </link>
  <joint
    name="joint_1"
    type="revolute">
    <origin
      xyz="0.13389 -0.20157 0.16797"
      rpy="1.5708 0 0.12516" />
    <parent
      link="base_link" />
    <child
      link="link_1" />
    <axis
      xyz="0 1 0" />
    <limit
      lower="-3.14"
      upper="3.14"
      effort="100"
      velocity="3" />
  </joint>
  <link
    name="link_2">
    <inertial>
      <origin
        xyz="0.048496 0.02011 0.004"
        rpy="0 0 0" />
      <mass
        value="0.01313" />
      <inertia
        ixx="9.796E-06"
        ixy="-3.9556E-06"
        ixz="1.7073E-20"
        iyy="1.7695E-05"
        iyz="-1.027E-20"
        izz="1.2521E-05" />
    </inertial>
    <visual>
      <origin
        xyz="0 0 0"
        rpy="0 0 0" />
      <geometry>
        <mesh
          filename="package://Aura_robot/meshes/link_2.STL" />
      </geometry>
      <material
        name="">
        <color
          rgba="0.79216 0.81961 0.93333 1" />
      </material>
    </visual>
    <collision>
      <origin
        xyz="0 0 0"
        rpy="0 0 0" />
      <geometry>
        <mesh
          filename="package://Aura_robot/meshes/link_2.STL" />
      </geometry>
    </collision>
  </link>
  <joint
    name="joint_2"
    type="revolute">
    <origin
      xyz="0.01 0.040197 0"
      rpy="0 0 1.3465" />
    <parent
      link="link_1" />
    <child
      link="link_2" />
    <axis
      xyz="0 0 1" />
    <limit
      lower="-3"
      upper="3"
      effort="100"
      velocity="3" />
  </joint>
  <link
    name="link_3">
    <inertial>
      <origin
        xyz="0.0022846 -0.0012213 0.0014929"
        rpy="0 0 0" />
      <mass
        value="0.042409" />
      <inertia
        ixx="9.2364E-06"
        ixy="-1.4625E-07"
        ixz="-5.1761E-08"
        iyy="1.5622E-05"
        iyz="7.5578E-08"
        izz="9.8257E-06" />
    </inertial>
    <visual>
      <origin
        xyz="0 0 0"
        rpy="0 0 0" />
      <geometry>
        <mesh
          filename="package://Aura_robot/meshes/link_3.STL" />
      </geometry>
      <material
        name="">
        <color
          rgba="0.79216 0.81961 0.93333 1" />
      </material>
    </visual>
    <collision>
      <origin
        xyz="0 0 0"
        rpy="0 0 0" />
      <geometry>
        <mesh
          filename="package://Aura_robot/meshes/link_3.STL" />
      </geometry>
    </collision>
  </link>
  <joint
    name="joint_3"
    type="revolute">
    <origin
      xyz="0.096991 0.04022 0"
      rpy="0 0 -1.3141" />
    <parent
      link="link_2" />
    <child
      link="link_3" />
    <axis
      xyz="0 0 1" />
    <limit
      lower="-3"
      upper="3"
      effort="100"
      velocity="3" />
  </joint>
  <link
    name="link_4">
    <inertial>
      <origin
        xyz="0.012429 -0.015197 -0.0030859"
        rpy="0 0 0" />
      <mass
        value="0.066899" />
      <inertia
        ixx="1.1055E-05"
        ixy="-7.2357E-08"
        ixz="9.5858E-08"
        iyy="1.7331E-05"
        iyz="7.2357E-08"
        izz="1.1055E-05" />
    </inertial>
    <visual>
      <origin
        xyz="0 0 0"
        rpy="0 0 0" />
      <geometry>
        <mesh
          filename="package://Aura_robot/meshes/link_4.STL" />
      </geometry>
      <material
        name="">
        <color
          rgba="0.79216 0.81961 0.93333 1" />
      </material>
    </visual>
    <collision>
      <origin
        xyz="0 0 0"
        rpy="0 0 0" />
      <geometry>
        <mesh
          filename="package://Aura_robot/meshes/link_4.STL" />
      </geometry>
    </collision>
  </link>
  <joint
    name="joint_4"
    type="revolute">
    <origin
      xyz="0.086605 0.0023025 0"
      rpy="3.1416 0 0.25822" />
    <parent
      link="link_3" />
    <child
      link="link_4" />
    <axis
      xyz="0 0 1" />
    <limit
      lower="-3"
      upper="3"
      effort="100"
      velocity="3" />
  </joint>
  <link
    name="gripper">
    <inertial>
      <origin
        xyz="0.034516 0.0072825 -0.0068125"
        rpy="0 0 0" />
      <mass
        value="0.052377" />
      <inertia
        ixx="9.5021E-06"
        ixy="-6.3691E-08"
        ixz="1.6795E-06"
        iyy="1.0667E-05"
        iyz="-4.0537E-08"
        izz="8.5903E-06" />
    </inertial>
    <visual>
      <origin
        xyz="0 0 0"
        rpy="0 0 0" />
      <geometry>
        <mesh
          filename="package://Aura_robot/meshes/gripper.STL" />
      </geometry>
      <material
        name="">
        <color
          rgba="0.79216 0.81961 0.93333 1" />
      </material>
    </visual>
    <collision>
      <origin
        xyz="0 0 0"
        rpy="0 0 0" />
      <geometry>
        <mesh
          filename="package://Aura_robot/meshes/gripper.STL" />
      </geometry>
    </collision>
  </link>
  <joint
    name="gripper_joint"
    type="revolute">
    <origin
      xyz="0.032619 -0.030395 -0.014"
      rpy="-3.139 0 0" />
    <parent
      link="link_4" />
    <child
      link="gripper" />
    <axis
      xyz="1 0 0" />
    <limit
      lower="-3.14"
      upper="3.14"
      effort="100"
      velocity="3" />
  </joint>
</robot>